Workbook

Sheet Cover
A1: BEN MEYER
A2: Cosmic Buildings Inc. — driver model
A3: Scenario model built from the workup's assumption registry
A4: As of 2026-09-16
A6: CONTENTS
A7: Read Me | B7: how to drive the model and what the colours mean
A8: Assumptions | B8: 23 drivers, each with a source and a tier
A9: Model | B9: 39 line items over 5 periods
A10: Sensitivity | B10: every driver ranked by how far it moves the answer
A11: Returns | B11: entry price, dilution, preference waterfall, MOIC and IRR
A13: COLOUR KEY
A14: Blue | B14: input or assumption — change these
A15: Black | B15: formula — do not overtype
A16: Green | B16: link from another sheet
A18: Public records only · Not investment advice

Sheet Read Me
A1: Cosmic Buildings Inc. — driver model
A3: Built | B3: 2026-09-16
A4: Units | B4: USD
A5: Periods | B5: 2026E, 2027E, 2028E, 2029E, 2030E
A7: HOW TO USE
A8: Scenario | B8: Assumptions!B3 switches every driver between Bear / Base / Bull at once.
A9: Edit here | B9: Only the blue Bear / Base / Bull cells on the Assumptions tab. Everything else is formulas.
A10: Yellow rows | B10: Confidence tier 'guess'. Nobody knows these numbers. Attack them first.
A12: COLOR KEY
A13: Blue text | B13: Hardcoded input you can change
A14: Black text | B14: Formula referencing this sheet
A15: Green text | B15: Formula referencing another sheet
A16: Yellow fill | B16: Guess-tier assumption — the diligence agenda
A18: CONFIDENCE TIERS
A19: observed | B19: Stated in a primary document
A20: inferred | B20: Derived from observed data, with the reasoning in the note
A21: analog | B21: Taken from a named comparable company or benchmark
A22: guess | B22: Nobody knows; a defensible number was chosen
A24: A WARNING | B24: This model is only as good as its worst load-bearing guess. Check the Sensitivity tab to find out which one that is.

Sheet Assumptions
A1: ASSUMPTIONS & PROVENANCE REGISTRY
A2: Company: | B2: Cosmic Buildings Inc.
A3: Scenario: | B3: Base | C3: <- switch here
A5: ID | B5: Assumption | C5: Unit | D5: Bear | E5: Base | F5: Bull | G5: Active | H5: Confidence | I5: Source | J5: Note
A6: leads_y1 | B6: Design-stage clients, 2026 entry | C6: clients | D6: 25 | E6: 40 | F6: 55 | G6: =INDEX($D6:$F6,MATCH($B$3,$D$5:$F$5,0)) -> 40 | H6: inferred | I6: 'around 40 clients in various stages of design or permitting' across the Palisades, Malibu and Altadena (Metropolis, 2026-02-27); 48 families in design a year earlier (LA Business Journal, 2025-08-25) | J6: Design-stage, not contracted. The company also publishes 45 free concept designs, which are offered to anyone and are not clients.
A7: lead_growth | B7: Growth in design-stage clients | C7: % | D7: -0.1 | E7: 0.2 | F7: 0.35 | G7: =INDEX($D7:$F7,MATCH($B$3,$D$5:$F$5,0)) -> 0.2 | H7: guess | I7: None. The two published counts (48 in Aug 2025, ~40 in Feb 2026) went down, not up | J7: Bear assumes the fire-rebuild surge fades as lots are sold rather than rebuilt; roughly 40% of Palisades lots that sell go to investors.
A8: lead_to_contract | B8: Design clients who sign a build contract | C8: % | D8: 0.12 | E8: 0.25 | F8: 0.4 | G8: =INDEX($D8:$F8,MATCH($B$3,$D$5:$F$5,0)) -> 0.25 | H8: inferred | I8: The company's own two figures on the same date: 48 families in design, 12 contracts signed (LA Business Journal, 2025-08-25) = 25% | J8: The obvious number to chase, and the model says chasing it barely matters: at base margins each delivered home contributes about $39,000 after the field staff it needs, against roughly $3.4M of fixed overhead. Converting more clients into contracts does not fix economics that lose money per home.
A9: deliveries_y1 | B9: Homes completed, 2026 | C9: homes | D9: 3 | E9: 6 | F9: 12 | G9: =INDEX($D9:$F9,MATCH($B$3,$D$5:$F$5,0)) -> 6 | H9: guess | I9: Two ADUs completed as of 2025-10 (Homes.com, reporter on site); one single-family about one third built at 2026-01 (CBS SF); company-stated 20-25 'in the process of building' | J9: Completions, not starts. Seeds the first year only; from 2027 deliveries follow the prior year's signed contracts.
A10: adu_share | B10: Share of deliveries that are ADUs | C10: % | D10: 0.7 | E10: 0.45 | F10: 0.25 | G10: =INDEX($D10:$F10,MATCH($B$3,$D$5:$F$5,0)) -> 0.45 | H10: guess | I10: The ADU line is the published product (100 units offered from March 2024); the fire rebuilds are custom houses at several times the value | J10: Bear is ADU-weighted because a backyard unit bills a fraction of a house. Mix is the quiet driver of revenue per delivery.
A11: adu_price | B11: Average ADU contract value | C11: $ | D11: 300000 | E11: 350000 | F11: 400000 | G11: =INDEX($D11:$F11,MATCH($B$3,$D$5:$F$5,0)) -> 350000 | H11: inferred | I11: Published list: $279,000 (380 sq ft), $359,000 (570 sq ft), $419,000 (720 sq ft); simple average $352,667 | J11: List, before upgrades, which the press reports at $1,000-$35,000. Bear assumes discounting to move units.
A12: adu_gm | B12: Gross margin, ADUs | C12: % | D12: 0.05 | E12: 0.18 | F12: 0.28 | G12: =INDEX($D12:$F12,MATCH($B$3,$D$5:$F$5,0)) -> 0.18 | H12: guess | I12: No cost data exists for either completed unit | J12: A repeatable product should out-earn bespoke work once the design is amortised. Nothing published tests that here.
A13: home_sqft | B13: Average custom home size | C13: sq ft | D13: 1800 | E13: 2200 | F13: 2800 | G13: =INDEX($D13:$F13,MATCH($B$3,$D$5:$F$5,0)) -> 2200 | H13: inferred | I13: The company quotes capacity per 2,000 sq ft home and names a 6,000 sq ft pipeline item; Palisades rebuild plans commonly run 1,900-4,600 sq ft | J13: Bigger houses are better for this model: fixed overhead per job spreads over more billable feet.
A14: home_psf | B14: Realised revenue per sq ft, custom | C14: $ | D14: 560 | E14: 640 | F14: 700 | G14: =INDEX($D14:$F14,MATCH($B$3,$D$5:$F$5,0)) -> 640 | H14: inferred | I14: Company-stated $550-700/sq ft (LA Business Journal; Metropolis); a reporter independently put actual LA projects at $600-700 (Homes.com, 2025-10-29) | J14: A site-built competitor in the same fire zones publishes $391/sq ft in the Palisades, so the pricing is not the cheap end of the market.
A15: home_gm | B15: Gross margin, custom homes | C15: % | D15: 0.06 | E15: 0.16 | F15: 0.24 | G15: =INDEX($D15:$F15,MATCH($B$3,$D$5:$F$5,0)) -> 0.16 | H15: analog | I15: D.R. Horton FY2025 10-K: revenue $34,250.4M less cost of revenue $26,134.2M = 23.7% | J15: That peer is the largest US production builder at scale, and its margin includes profit on land it buys and sells. Cosmic never owns the lot, so the peer figure is a ceiling. Bear is the fixed-price-overrun case.
A16: psf_change | B16: Annual change in realised pricing | C16: % | D16: -0.06 | E16: -0.02 | F16: 0.02 | G16: =INDEX($D16:$F16,MATCH($B$3,$D$5:$F$5,0)) -> -0.02 | H16: guess | I16: None | J16: Headline ADU prices held at $279k/$359k/$419k from 2024 to 2026 while the stated areas shrank (395->380, 595->570, 750->720 sq ft) - a rise per square foot, not a cut.
A17: cost_us | B17: Loaded cost per US employee | C17: $ | D17: 205000 | E17: 185000 | F17: 165000 | G17: =INDEX($D17:$F17,MATCH($B$3,$D$5:$F$5,0)) -> 185000 | H17: analog | I17: San Francisco and Los Angeles loaded cost for senior commercial and construction staff, inclusive of employer taxes and benefits | J17: Loaded, not salary. The company publishes no compensation data.
... A28: rs_per_client | B28: Belgrade design staff per design-stage client | C28: people | D28: 0.45 | E28: 0.3 | F28: 0.2 | G28: =INDEX($D28:$F28,MATCH($B$3,$D$5:$F$5,0)) -> 0.3 | H28: inferred | I28: Derived: 8 core plus 0.30 x 40 design clients reconciles to the 20 Belgrade staff implied by the LinkedIn count less identifiable US roles | J28: Free concept designs are produced here, so this team carries the cost of work that has not been paid for. Bull assumes the automation genuinely reduces hours per client.

Sheet Model
A1: COSMIC BUILDINGS INC. — OPERATING MODEL
A2: Units: USD. Scenario driven from Assumptions!B3.
A4: Scenario: | B4: =Assumptions!$B$3 -> Base
A6: Line item | B6: 2026E | C6: 2027E | D6: 2028E | E6: 2029E | F6: 2030E
A7: PIPELINE AND CAPACITY
A8: Design-stage clients | B8: =Assumptions!$G$6 -> 40 | C8: =B8*(1+Assumptions!$G$7) -> 48 | D8: =C8*(1+Assumptions!$G$7) -> 57.6 | E8: =D8*(1+Assumptions!$G$7) -> 69.12 | F8: =E8*(1+Assumptions!$G$7) -> 82.944
A9: Build contracts signed | B9: =B8*Assumptions!$G$8 -> 10 | C9: =C8*Assumptions!$G$8 -> 12 | D9: =D8*Assumptions!$G$8 -> 14.4 | E9: =E8*Assumptions!$G$8 -> 17.28 | F9: =F8*Assumptions!$G$8 -> 20.736
A10: Homes ready to deliver | B10: =Assumptions!$G$9 -> 6 | C10: =B9 -> 10 | D10: =C9 -> 12 | E10: =D9 -> 14.4 | F10: =E9 -> 17.28
A11: Microfactories in service | B11: =1 -> 1 | C11: =B11+Assumptions!$G$22 -> 2 | D11: =C11+Assumptions!$G$22 -> 3 | E11: =D11+Assumptions!$G$22 -> 4 | F11: =E11+Assumptions!$G$22 -> 5
A12: Framing capacity (homes) | B12: =B11*Assumptions!$G$21 -> 25 | C12: =C11*Assumptions!$G$21 -> 50 | D12: =D11*Assumptions!$G$21 -> 75 | E12: =E11*Assumptions!$G$21 -> 100 | F12: =F11*Assumptions!$G$21 -> 125
A13: Homes delivered | B13: =MIN(B10,B12) -> 6 | C13: =MIN(C10,C12) -> 10 | D13: =MIN(D10,D12) -> 12 | E13: =MIN(E10,E12) -> 14.4 | F13: =MIN(F10,F12) -> 17.28
A14: REVENUE BY PRODUCT
A15: ADUs delivered | B15: =B13*Assumptions!$G$10 -> 2.7 | C15: =C13*Assumptions!$G$10 -> 4.5 | D15: =D13*Assumptions!$G$10 -> 5.4 | E15: =E13*Assumptions!$G$10 -> 6.48 | F15: =F13*Assumptions!$G$10 -> 7.776
A16: Custom homes delivered | B16: =B13*(1-Assumptions!$G$10) -> 3.3 | C16: =C13*(1-Assumptions!$G$10) -> 5.5 | D16: =D13*(1-Assumptions!$G$10) -> 6.6 | E16: =E13*(1-Assumptions!$G$10) -> 7.92 | F16: =F13*(1-Assumptions!$G$10) -> 9.504
A17: ADU price | B17: =Assumptions!$G$11 -> 350000 | C17: =B17*(1+Assumptions!$G$16) -> 343000 | D17: =C17*(1+Assumptions!$G$16) -> 336140 | E17: =D17*(1+Assumptions!$G$16) -> 329417.2 | F17: =E17*(1+Assumptions!$G$16) -> 322828.86
A18: Custom revenue per sq ft | B18: =Assumptions!$G$14 -> 640 | C18: =B18*(1+Assumptions!$G$16) -> 627.2 | D18: =C18*(1+Assumptions!$G$16) -> 614.656 | E18: =D18*(1+Assumptions!$G$16) -> 602.36288 | F18: =E18*(1+Assumptions!$G$16) -> 590.31562
A19: ADU revenue | B19: =B15*B17 -> 945000 | C19: =C15*C17 -> 1543500 | D19: =D15*D17 -> 1815156 | E19: =E15*E17 -> 2134623.5 | F19: =F15*F17 -> 2510317.2
A20: Custom home revenue | B20: =B16*Assumptions!$G$13*B18 -> 4646400 | C20: =C16*Assumptions!$G$13*C18 -> 7589120 | D20: =D16*Assumptions!$G$13*D18 -> 8924805.1 | E20: =E16*Assumptions!$G$13*E18 -> 10495571 | F20: =F16*Assumptions!$G$13*F18 -> 12342791
A21: Total revenue | B21: =B19+B20 -> 5591400 | C21: =C19+C20 -> 9132620 | D21: =D19+D20 -> 10739961 | E21: =E19+E20 -> 12630194 | F21: =F19+F20 -> 14853108
A22: GROSS PROFIT
A23: Gross profit, ADUs | B23: =B19*Assumptions!$G$12 -> 170100 | C23: =C19*Assumptions!$G$12 -> 277830 | D23: =D19*Assumptions!$G$12 -> 326728.08 | E23: =E19*Assumptions!$G$12 -> 384232.22 | F23: =F19*Assumptions!$G$12 -> 451857.09
A24: Gross profit, custom homes | B24: =B20*Assumptions!$G$15 -> 743424 | C24: =C20*Assumptions!$G$15 -> 1214259.2 | D24: =D20*Assumptions!$G$15 -> 1427968.8 | E24: =E20*Assumptions!$G$15 -> 1679291.3 | F24: =F20*Assumptions!$G$15 -> 1974846.6
A25: Gross profit | B25: =B23+B24 -> 913524 | C25: =C23+C24 -> 1492089.2 | D25: =D23+D24 -> 1754696.9 | E25: =E23+E24 -> 2063523.6 | F25: =F23+F24 -> 2426703.7
A26: Cost of homes delivered | B26: =B21-B25 -> 4677876 | C26: =C21-C25 -> 7640530.8 | D26: =D21-D25 -> 8985264.2 | E26: =E21-E25 -> 10566671 | F26: =F21-F25 -> 12426405
A27: Blended gross margin | B27: =B25/B21 -> 0.16338019 | C27: =C25/C21 -> 0.16338019 | D27: =D25/D21 -> 0.16338019 | E27: =E25/E21 -> 0.16338019 | F27: =F25/F21 -> 0.16338019
A28: OPERATING EXPENSE
A29: US headcount | B29: =Assumptions!$G$25+B13*Assumptions!$G$26 -> 10 | C29: =Assumptions!$G$25+C13*Assumptions!$G$26 -> 12 | D29: =Assumptions!$G$25+D13*Assumptions!$G$26 -> 13 | E29: =Assumptions!$G$25+E13*Assumptions!$G$26 -> 14.2 | F29: =Assumptions!$G$25+F13*Assumptions!$G$26 -> 15.64
A30: Belgrade headcount | B30: =Assumptions!$G$27+B8*Assumptions!$G$28 -> 20 | C30: =Assumptions!$G$27+C8*Assumptions!$G$28 -> 22.4 | D30: =Assumptions!$G$27+D8*Assumptions!$G$28 -> 25.28 | E30: =Assumptions!$G$27+E8*Assumptions!$G$28 -> 28.736 | F30: =Assumptions!$G$27+F8*Assumptions!$G$28 -> 32.8832
A31: Total headcount | B31: =B29+B30 -> 30 | C31: =C29+C30 -> 34.4 | D31: =D29+D30 -> 38.28 | E31: =E29+E30 -> 42.936 | F31: =F29+F30 -> 48.5232
A32: US payroll | B32: =B29*Assumptions!$G$17 -> 1850000 | C32: =C29*Assumptions!$G$17 -> 2220000 | D32: =D29*Assumptions!$G$17 -> 2405000 | E32: =E29*Assumptions!$G$17 -> 2627000 | F32: =F29*Assumptions!$G$17 -> 2893400
A33: Belgrade payroll | B33: =B30*Assumptions!$G$18 -> 900000 | C33: =C30*Assumptions!$G$18 -> 1008000 | D33: =D30*Assumptions!$G$18 -> 1137600 | E33: =E30*Assumptions!$G$18 -> 1293120 | F33: =F30*Assumptions!$G$18 -> 1479744
A34: Non-payroll overhead | B34: =(B32+B33)*Assumptions!$G$19 -> 605000 | C34: =(C32+C33)*Assumptions!$G$19 -> 710160 | D34: =(D32+D33)*Assumptions!$G$19 -> 779372 | E34: =(E32+E33)*Assumptions!$G$19 -> 862426.4 | F34: =(F32+F33)*Assumptions!$G$19 -> 962091.68
A35: Total operating expense | B35: =B32+B33+B34 -> 3355000 | C35: =C32+C33+C34 -> 3938160 | D35: =D32+D33+D34 -> 4321972 | E35: =E32+E33+E34 -> 4782546.4 | F35: =F32+F33+F34 -> 5335235.7
A36: EBITDA | B36: =B25-B35 -> -2441476 | C36: =C25-C35 -> -2446070.8 | D36: =D25-D35 -> -2567275.1 | E36: =E25-E35 -> -2719022.8 | F36: =F25-F35 -> -2908532
A37: UNIT ECONOMICS, PER HOME DELIVERED
A38: Revenue per home | B38: =B21/MAX(1,B13) -> 931900 | C38: =C21/MAX(1,C13) -> 913262 | D38: =D21/MAX(1,D13) -> 894996.76 | E38: =E21/MAX(1,E13) -> 877096.82 | F38: =F21/MAX(1,F13) -> 859554.89
A39: Gross profit per home | B39: =B25/MAX(1,B13) -> 152254 | C39: =C25/MAX(1,C13) -> 149208.92 | D39: =D25/MAX(1,D13) -> 146224.74 | E39: =E25/MAX(1,E13) -> 143300.25 | F39: =F25/MAX(1,F13) -> 140434.24
A40: Operating expense per home | B40: =B35/MAX(1,B13) -> 559166.67 | C40: =C35/MAX(1,C13) -> 393816 | D40: =D35/MAX(1,D13) -> 360164.33 | E40: =E35/MAX(1,E13) -> 332121.28 | F40: =F35/MAX(1,F13) -> 308752.06
A41: EBITDA per home | B41: =B36/MAX(1,B13) -> -406912.67 | C41: =C36/MAX(1,C13) -> -244607.08 | D41: =D36/MAX(1,D13) -> -213939.59 | E41: =E36/MAX(1,E13) -> -188821.03 | F41: =F36/MAX(1,F13) -> -168317.82
A42: WORKING CAPITAL, CAPITAL SPEND AND CASH
...

Sheet Sensitivity
A1: SENSITIVITY & DILIGENCE PRIORITY
A2: STATIC SNAPSHOT computed when this workbook was built. It does not recalculate. Rebuild the model after changing assumptions.
A4: IMPACT ON CLOSING CASH, BEFORE ANY NEW RAISE, 2030E
A5: Each assumption moved bear -> bull alone, all others at base. Sorted by swing.
A6: Assumption | B6: At bear | C6: At base | D6: At bull | E6: Swing | F6: Share of largest | G6: Confidence
A7: US field and PM staff per home delivered | B7: -18551492 | C7: -13163582 | D7: -10469627 | E7: 8081865.6 | F7: 1 | G7: guess
A8: Gross margin, custom homes | B8: -17563451 | C8: -13163582 | D8: -9643686.9 | E8: 7919763.7 | F8: 0.97994251 | G8: analog
A9: Opening cash, 2026 | B9: -15663582 | C9: -13163582 | D9: -8163581.9 | E9: 7500000 | F9: 0.92800355 | G9: guess
A10: Growth in design-stage clients | B10: -10467770 | C10: -13163582 | D10: -15226564 | E10: 4758794.5 | F10: 0.58882376 | G10: guess
A11: US core team (fixed) | B11: -15420582 | C11: -13163582 | D11: -10906582 | E11: 4514000 | F11: 0.55853441 | G11: inferred
A12: Microfactories added per year | B12: -10913582 | C12: -13163582 | D12: -15413582 | E12: 4500000 | F12: 0.55680213 | G12: guess
A13: Belgrade design staff per design-stage client | B13: -15614845 | C13: -13163582 | D13: -11529407 | E13: 4085438.4 | F13: 0.50550685 | G13: inferred
A14: Design-stage clients, 2026 entry | B14: -11268142 | C14: -13163582 | D14: -15059022 | E14: 3790879.4 | F14: 0.46905994 | G14: inferred
A15: Share of deliveries that are ADUs | B15: -14948878 | C15: -13163582 | D15: -11735345 | E15: 3213533.2 | F15: 0.3976227 | G15: guess
A16: Loaded cost per US employee | B16: -14745678 | C16: -13163582 | D16: -11581486 | E16: 3164192 | F16: 0.39151752 | G16: analog
A17: Loaded cost per Belgrade employee | B17: -14741032 | C17: -13163582 | D17: -12059367 | E17: 2681665.4 | F17: 0.33181267 | G17: analog
A18: Non-payroll opex, as % of payroll | B18: -14588691 | C18: -13163582 | D18: -11916611 | E18: 2672079.6 | F18: 0.33062658 | G18: analog
... A29: Homes framed per microfactory per year | B29: -13163582 | C29: -13163582 | D29: -13163582 | E29: 0 | F29: 0 | G29: guess
A31: DILIGENCE PRIORITY
A32: Highest-leverage guess: US field and PM staff per home delivered. Establishing this number is worth more than refining anything else in the model.
A35: CLOSING CASH, BEFORE ANY NEW RAISE (2030E): Design clients who sign a build contract vs Gross margin, custom homes
A36: Design clients who sign a build contract \ Gross margin, custom homes | B36: 0.11 | C36: 0.14 | D36: 0.16 | E36: 0.18 | F36: 0.21
A37: 0.17 | B37: -14663252 | C37: -13890620 | D37: -13117988 | E37: -12345356 | F37: -11572724
A38: 0.21 | B38: -14969385 | C38: -14055085 | D38: -13140785 | E38: -12226485 | F38: -11312184
A39: 0.25 | B39: -15275519 | C39: -14219550 | D39: -13163582 | E39: -12107613 | F39: -11051645
A40: 0.29 | B40: -15581652 | C40: -14384016 | D40: -13186379 | E40: -11988742 | F40: -10791105
A41: 0.33 | B41: -15887786 | C41: -14548481 | D41: -13209176 | E41: -11869871 | F41: -10530566

Sheet Returns
A1: RETURNS — ENTRY, DILUTION, WATERFALL
A2: Blue cells are inputs. Everything else is a formula. Exit value is driven off the model's terminal year.
A4: ENTRY
A5: Pre-money valuation | B5: 20000000 | C5: What you pay in at
A6: Investment | B6: 2000000 | C6: Your cheque
A7: Post-money valuation | B7: =B5+B6 -> 22000000
A8: Entry ownership | B8: =B6/B7 -> 0.090909091
A10: DILUTION TO EXIT
A11: Dilution per subsequent round | B11: 0.22 | C11: New money issued at each future round
A12: Rounds before exit | B12: 2 | C12: How many more times the cap table opens
A13: Exit ownership | B13: =B8*(1-B11)^B12 -> 0.055309091 | C13: Ownership at exit is the only ownership that pays. Entry ownership is a number you stop owning immediately.
A15: EXIT
A16: Terminal revenue (2030E) | B16: 14853108 | C16: From the Model sheet, base scenario
A17: Exit multiple on revenue | B17: 1.2 | C17: Name the peers this comes from in the workup
A18: Exit enterprise value | B18: =B16*B17 -> 17823730
A19: Years to exit | B19: 5
A21: WATERFALL
A22: Liquidation preference multiple | B22: 1 | C22: 1.0x non-participating is the common seed case
A23: Preference amount | B23: =B6*B22 -> 2000000
A24: Value if converted to common | B24: =B18*B13 -> 985814.31
A25: Proceeds to this investment | B25: =MAX(B23,B24) -> 2000000 | C25: Non-participating: the better of the preference or the converted share, never both. Below the crossover the preference is all that protects you.
A27: RESULT
A28: Multiple on invested capital | B28: =B25/B6 -> 1
A29: IRR | B29: =IF(B28<=0,-1,B28^(1/B19)-1) -> 0
A31: No hurdle set. Put the return this investment has to clear in the spec's returns.hurdle_irr and this sheet will check against it.
A34: What this does not cover: option pool expansion, pro-rata follow-ons, participation caps, seniority stacks between rounds, secondary sales, and any structure beyond a single preference. It is a first-pass sanity check on the entry price, not a cap table.
